Workbook

Sheet Iowa_City_CSD_General_Fund_Bala
B1: Iowa City Community School District - General Fund Balance Sheet (as of June 30)
C2: Audit | D2: Audit | E2: Audit | F2: Audit | G2: Audit | H2: Audit | I2: Audit | J2: Audit | K2: Audit | L2: Audit | M2: CAR
B3: Line item (US dollars) | C3: FY2015 | D3: FY2016 | E3: FY2017 | F3: FY2018 | G3: FY2019 | H3: FY2020 | I3: FY2021 | J3: FY2022 | K3: FY2023 | L3: FY2024 | M3: FY2025 | O3: 25 vs 24 ($) | P3: 25 vs 24 (%)
B4: Assets
A5: 1 | B5: Cash, cash equivalents and investments | C5: 25599301 | D5: 33270812 | E5: 36965401 | F5: 35749416 | G5: 29661358 | H5: 24963852 | I5: 21761592 | J5: 21475952 | K5: 19012680 | L5: 22536992 | M5: ='FY2025 BS by Fund'!C3 -> 43685677 | O5: =M5-L5 -> 21148685 | P5: =O5/L5 -> 0.93839875
A6: =A5+1 -> 2 | B6: Property tax receivable - current year | C6: 232369 | D6: 200376 | E6: 172824 | F6: 248698 | G6: 226346 | H6: 419384 | I6: 560338 | J6: 234203 | K6: 366102 | L6: 429762 | M6: ='FY2025 BS by Fund'!C4-'FY2025 BS by Fund'!C35 -> 379454.26 | O6: =M6-L6 -> -50307.74 | P6: =O6/L6 -> -0.11705954
A7: =A6+1 -> 3 | B7: Property tax receivable - succeeding year | C7: 56420267 | D7: 60238767 | E7: 62483923 | F7: 63927908 | G7: 65789035 | H7: 72666630 | I7: 72389732 | J7: 74768537 | K7: 75474753 | L7: 84046760 | M7: ='FY2025 BS by Fund'!C35 -> 83672537 | O7: =M7-L7 -> -374223.19 | P7: =O7/L7 -> -0.0044525594
A8: =A7+1 -> 4 | B8: Income surtax receivable | C8: 6270674 | D8: 6393586 | E8: 6816288 | F8: 6820672 | G8: 7117360 | H8: 7403410 | I8: 6692192 | J8: 7824520 | K8: 7976285 | L8: 6986431 | M8: ='FY2025 BS by Fund'!C36 -> 7070437 | O8: =M8-L8 -> 84006 | P8: =O8/L8 -> 0.012024165
A9: =A8+1 -> 5 | B9: Other receivables | C9: 786056 | D9: 173561 | E9: 147116 | F9: 343272 | G9: 702720 | H9: 2155541 | I9: 996184 | J9: 223250 | K9: 641083 | L9: 385129 | M9: ='FY2025 BS by Fund'!C7 -> 487319.26 | O9: =M9-L9 -> 102190.26 | P9: =O9/L9 -> 0.26534034
A10: =A9+1 -> 6 | B10: Due from other governments | C10: 2148465 | D10: 1978107 | E10: 1966701 | F10: 1988224 | G10: 2373369 | H10: 2252396 | I10: 10458625 | J10: 7722440 | K10: 14223011 | L10: 5626319 | M10: ='FY2025 BS by Fund'!C6-'FY2025 BS by Fund'!C36 -> 2568340 | O10: =M10-L10 -> -3057979 | P10: =O10/L10 -> -0.54351327
A11: =A10+1 -> 7 | B11: Due from other funds | C11: 1329952 | D11: 11132 | E11: 750616 | F11: 93140 | G11: 27801 | H11: 275994 | I11: 150423 | J11: 177298 | K11: 156679 | L11: 29093296 | M11: ='FY2025 BS by Fund'!C5 -> 974445.71 | O11: =M11-L11 -> -28118850 | P11: =O11/L11 -> -0.96650618
A12: =A11+1 -> 8 | B12: Prepaid items | C12: 1095801 | D12: 1127628 | E12: 1251954 | F12: 1395556 | G12: 1472184 | H12: 1552575 | I12: 1317074 | J12: 1738981 | K12: 1702154 | L12: 67836 | M12: ='FY2025 BS by Fund'!C9+'FY2025 BS by Fund'!C8+'FY2025 BS by Fund'!C15 -> 1303183.9 | O12: =M12-L12 -> 1235347.9 | P12: =O12/L12 -> 18.210802
A13: =A12+1 -> 9 | B13: Total assets | C13: 93882885 | D13: 103393969 | E13: 110554823 | F13: 110566886 | G13: 107370173 | H13: 111689782 | I13: 114326160 | J13: 114165181 | K13: 119552747 | L13: =SUM(L5:L12) -> 149172525 | M13: =SUM(M5:M12) -> 1.4014139e+08 | O13: =M13-L13 -> -9031131 | P13: =O13/L13 -> -0.060541517
A14: =A13+1 -> 10 | B14: Liabilities
A15: =A14+1 -> 11 | B15: Accounts payable | C15: 2013166 | D15: 1895636 | E15: 2636705 | F15: 2776112 | G15: 2061443 | H15: 2416119 | I15: 1763278 | J15: 1933142 | K15: 1431069 | L15: 1735139 | M15: ='FY2025 BS by Fund'!C22+'FY2025 BS by Fund'!C21+'FY2025 BS by Fund'!C23 -> 3121264.6 | O15: =M15-L15 -> 1386125.6 | P15: =O15/L15 -> 0.79885564
A16: =A15+1 -> 12 | B16: Salaries and benefits payable / accrued liabilities | C16: 13190317 | D16: 13706046 | E16: 14762330 | F16: 15908169 | G16: 17455439 | H16: 16465994 | I16: 17373534 | J16: 19286079 | K16: 19887707 | L16: 17190017 | M16: ='FY2025 BS by Fund'!C26+'FY2025 BS by Fund'!C27 -> 26795468 | O16: =M16-L16 -> 9605450.7 | P16: =O16/L16 -> 0.55878076
A17: =A16+1 -> 13 | B17: Due to other funds | C17: 2552 | D17: 661001 | E17: 10572 | F17: 8086 | G17: 17064 | H17: 29976 | I17: 22924 | J17: 71144 | K17: 1000000 | L17: 20073735 | M17: ='FY2025 BS by Fund'!C20 -> 0 | O17: =M17-L17 -> -20073735 | P17: =O17/L17 -> -1
A18: =A17+1 -> 14 | B18: Due to fiduciary funds | G18: 0 | H18: 3120 | M18: 0
A19: =A18+1 -> 15 | B19: Unearned revenue | C19: 41627 | D19: 68582 | E19: 11900 | F19: 14516 | G19: 29788 | H19: 1464393 | I19: 194350 | J19: 218705 | K19: 1306772 | M19: ='FY2025 BS by Fund'!C28 -> 0
A20: =A19+1 -> 16 | B20: Total liabilities | C20: 15247662 | D20: 16331265 | E20: 17421507 | F20: 18706883 | G20: 19563734 | H20: 20379602 | I20: 19354086 | J20: 21509070 | K20: 23625548 | L20: =SUM(L15:L19) -> 38998891 | M20: =SUM(M15:M19) -> 29916732 | O20: =M20-L20 -> -9082158.7 | P20: =O20/L20 -> -0.23288249
A21: =A20+1 -> 17 | B21: Deferred inflows of resources
A22: =A21+1 -> 18 | B22: Unavailable revenue - property tax | C22: 56420267 | D22: 60238767 | E22: 62483923 | F22: 63927908 | G22: 65789035 | H22: 72666630 | I22: 72389732 | J22: 74768537 | K22: 75474753 | L22: 84046760 | M22: ='FY2025 BS by Fund'!C35 -> 83672537 | O22: =M22-L22 -> -374223.19 | P22: =O22/L22 -> -0.0044525594
A23: =A22+1 -> 19 | B23: Unavailable revenue - income surtax | C23: 6270674 | D23: 6393586 | E23: 6816288 | F23: 6820672 | G23: 7117360 | H23: 7403410 | I23: 6692192 | J23: 7824520 | K23: 7976285 | L23: 6986431 | M23: ='FY2025 BS by Fund'!C36 -> 7070437 | O23: =M23-L23 -> 84006 | P23: =O23/L23 -> 0.012024165
A24: =A23+1 -> 20 | B24: Unavailable revenue - federal sources | K24: 2324940 | M24: 0
A25: =A24+1 -> 21 | B25: Unavailable revenue - other | L25: 87390 | M25: ='FY2025 BS by Fund'!C37 -> 1188013.1 | O25: =M25-L25 -> 1100623.1 | P25: =O25/L25 -> 12.594382
A26: =A25+1 -> 22 | B26: Total deferred inflows of resources | C26: 62690941 | D26: 66632353 | E26: 69300211 | F26: 70748580 | G26: 72906395 | H26: 80070040 | I26: 79081924 | J26: 82593057 | K26: 85775978 | L26: =SUM(L22:L25) -> 91120581 | M26: =SUM(M22:M25) -> 91930987 | O26: =M26-L26 -> 810405.89 | P26: =O26/L26 -> 0.0088937744
A27: =A26+1 -> 23 | B27: Fund balances
A28: =A27+1 -> 24 | B28: Nonspendable | C28: 1095801 | D28: 1127628 | E28: 1251954 | F28: 1395556 | G28: 1472184 | H28: 1552575 | I28: 1316399 | J28: 1738981 | K28: 1702154 | L28: 67836 | M28: ='FY2025 BS by Fund'!C42 -> 1276719.8 | O28: =M28-L28 -> 1208883.8 | P28: =O28/L28 -> 17.820682
A29: =A28+1 -> 25 | B29: Restricted | C29: 3303867 | D29: 3963463 | E29: 4030600 | F29: 2478299 | G29: 2157358 | H29: 2811326 | I29: 2920281 | J29: 2967523 | K29: 3488724 | L29: 2703361 | M29: ='FY2025 BS by Fund'!C43 -> 4745545.3 | O29: =M29-L29 -> 2042184.3 | P29: =O29/L29 -> 0.75542418
A30: =A29+1 -> 26 | B30: Unassigned | C30: 11544614 | D30: 15339260 | E30: 18550551 | F30: 17237568 | G30: 11270502 | H30: 6876239 | I30: 11653470 | J30: 5356550 | K30: 4960343 | L30: 16281856 | M30: ='FY2025 BS by Fund'!C46 -> 12271410 | O30: =M30-L30 -> -4010446.3 | P30: =O30/L30 -> -0.24631383
A31: =A30+1 -> 27 | B31: Total fund balances | C31: 15944282 | D31: 20430351 | E31: 23833105 | F31: 21111423 | G31: 14900044 | H31: 11240140 | I31: 15890150 | J31: 10063054 | K31: 10151221 | L31: =SUM(L28:L30) -> 19053053 | M31: =SUM(M28:M30) -> 18293675 | O31: =M31-L31 -> -759378.19 | P31: =O31/L31 -> -0.039855985
A32: =A31+1 -> 28 | B32: Total liabilities, deferred inflows and fund balances | C32: 93882885 | D32: 103393969 | E32: 110554823 | F32: 110566886 | G32: 107370173 | H32: 111689782 | I32: 114326160 | J32: 114165181 | K32: 119552747 | L32: =L20+L26+L31 -> 149172525 | M32: =M20+M26+M31 -> 1.4014139e+08 | O32: =M32-L32 -> -9031131 | P32: =O32/L32 -> -0.060541517

Sheet FY2025 BS by Fund
A1: Line | B1: Description | C1: General Fund | D1: Non-Fiduciary Scholarship Funds | E1: Student Activity Fund | F1: Management Levy Fund | G1: Entreprenurial Education Fund | H1: PERL Fund | I1: AEA Sp Ed Inst Fund | J1: AEA JH Inst Fund | K1: Support Trust Fund | L1: Disaster Recovery Fund | M1: Library Levy Fund | N1: SAVE Statewide Sales and Services Tax Fund | O1: PPEL Fund | P1: Other Capital Project Funds | Q1: Debt Service Fund | R1: Permanent Funds | S1: Enterprise Funds | T1: Internal Service Funds | U1: Trust Funds | V1: Custodial Funds | W1: Total
B2: CURRENT ASSETS
A3: 1 | B3: Cash & Investments | C3: 43685677 | E3: 1009917.3 | F3: 5560131.4 | N3: 9247528.7 | O3: 9749455.3 | P3: 391322.94 | Q3: 150040.26 | S3: 6634724.4 | T3: 15432281 | U3: 128731.32 | W3: 91989809
A4: 2 | B4: Taxes Receivable | C4: 84051991 | F4: 13000752 | O4: 13107010 | Q4: 13469293 | W4: 1.2362905e+08
A5: 3 | B5: Interfund Receivables | C5: 974445.71 | E5: 408.62 | W5: 974854.33
A6: 4 | B6: Intergovernmental Receivables | C6: 9638777 | N6: 1994425.4 | S6: 776618.35 | W6: 12409821
A7: 5 | B7: Other Receivables | C7: 487319.26 | E7: 40 | W7: 487359.26
A8: 6 | B8: Inventories | C8: 53228.9 | S8: 185193.53 | W8: 238422.43
A9: 7 | B9: Prepaid Expenses | C9: 1223490.9 | N9: 5626.87 | O9: 55252.93 | S9: 31098.16 | W9: 1315468.9
A10: 8 | B10: Other Current Assets
A11: 9 | B11: TOTAL CURRENT ASSETS | C11: 1.4011493e+08 | E11: 1010365.9 | F11: 18560884 | N11: 11247581 | O11: 22911719 | P11: 391322.94 | Q11: 13619333 | S11: 7627634.4 | T11: 15432281 | U11: 128731.32 | W11: 2.3104478e+08
A12: 10 | B12: Long-Term Assets | S12: 990427.96 | W12: 990427.96
A13: 11 | B13: Total Assets | C13: 1.4011493e+08 | E13: 1010365.9 | F13: 18560884 | N13: 11247581 | O13: 22911719 | P13: 391322.94 | Q13: 13619333 | S13: 8618062.4 | T13: 15432281 | U13: 128731.32 | W13: 2.3203521e+08
B14: DEFERRED OUTFLOWS OF RESOURCES
A15: 12 | B15: Deferred Outflows of Resources | C15: 26464.14 | W15: 26464.14
A16: 13 | B16: Deferred Outflows of Resources related to Pensions and OPEB | S16: 400175 | W16: 400175
A17: 14 | B17: Total Deferred Outflows of Resources | C17: 26464.14 | S17: 400175 | W17: 426639.14
A18: 15 | B18: TOTAL ASSETS AND DEFERRED OUTFLOWS OF RESOURCES | C18: 1.4014139e+08 | E18: 1010365.9 | F18: 18560884 | N18: 11247581 | O18: 22911719 | P18: 391322.94 | Q18: 13619333 | S18: 9018237.4 | T18: 15432281 | U18: 128731.32 | W18: 2.3246185e+08
B19: CURRENT LIABILITIES
A20: 16 | B20: Interfund Payables | E20: 974854.33 | W20: 974854.33
A21: 17 | B21: Intergovernmental Payables | C21: 82776.27 | W21: 82776.27
A22: 18 | B22: Other Payables | C22: 3038488.3 | E22: 35511.59 | N22: 957974.47 | O22: 1389410.3 | P22: 217583.55 | S22: 49024.88 | U22: 1629.36 | W22: 5689622.5
A23: 19 | B23: Contracts Payable | N23: 1009828.9 | O23: 125561.73 | P23: 173739.39 | W23: 1309130
A24: 20 | B24: Bonds Payable
A25: 21 | B25: Loans Payable
A26: 22 | B26: Accrued Expenses | C26: 13281045 | N26: 27996.71 | T26: 1515321.5 | W26: 14824363
A27: 23 | B27: Payroll Deductions & Withholdings Payable | C27: 13514422 | N27: 41584.66 | S27: 185981.78 | U27: 535327.3 | V27: 11167.5 | W27: 14288484
A28: 24 | B28: Advances of Federal Grants/Unearned Revenues | S28: 56869.44 | W28: 56869.44
A29: 25 | B29: Other Current Liabilities
A30: 26 | B30: TOTAL CURRENT LIABILITIES | C30: 29916732 | E30: 1010365.9 | N30: 2037384.7 | O30: 1514972.1 | P30: 391322.94 | S30: 291876.1 | T30: 2050648.8 | U30: 12796.86 | W30: 37226100
A31: 27 | B31: Net Pension Liabilities | S31: 1249537 | W31: 1249537
A32: 28 | B32: Long-Term Liabilities | S32: 315707.41 | W32: 315707.41
A33: 29 | B33: Total Liabilities | C33: 29916732 | E33: 1010365.9 | N33: 2037384.7 | O33: 1514972.1 | P33: 391322.94 | S33: 1857120.5 | T33: 2050648.8 | U33: 12796.86 | W33: 38791344
B34: DEFERRED INFLOWS OF RESOURCES
A35: 30 | B35: Deferred Inflows for Succeeding Year Property Taxes Receivable | C35: 83672537 | F35: 12942151 | O35: 13043375 | Q35: 13403898 | W35: 1.2306196e+08
A36: 31 | B36: Deferred Inflows for Income Surtax Receivable | C36: 7070437 | W36: 7070437
A37: 32 | B37: Deferred Inflows for Miscellaneous Receivables not Received Within 60 Days | C37: 1188013.1 | W37: 1188013.1
A38: 33 | B38: Deferred Inflows of Resources related to Pensions and OPEB | S38: 64068 | W38: 64068
A39: 34 | B39: Deferred Inflows of Resources | C39: 91930987 | F39: 12942151 | O39: 13043375 | Q39: 13403898 | S39: 64068 | W39: 1.3138448e+08
B40: EQUITY
...
